Watching for file changes with StatReloader
Exception in thread django-main-thread:
Traceback (most recent call last):
  File "/usr/lib64/python3.8/threading.py", line 932, in _bootstrap_inner
    self.run()
  File "/usr/lib64/python3.8/threading.py", line 870, in run
    self._target(*self._args, **self._kwargs)
  File "/home/vagrant/.local/share/virtualenvs/vagrant-gKDsaKU3/lib/python3.8/site-packages/django/utils/autoreload.py", line 64, in wrapper
    fn(*args, **kwargs)
  File "/home/vagrant/.local/share/virtualenvs/vagrant-gKDsaKU3/lib/python3.8/site-packages/django/core/management/commands/runserver.py", line 124, in inner_run
    self.check(display_num_errors=True)
  File "/home/vagrant/.local/share/virtualenvs/vagrant-gKDsaKU3/lib/python3.8/site-packages/django/core/management/base.py", line 438, in check
    all_issues = checks.run_checks(
  File "/home/vagrant/.local/share/virtualenvs/vagrant-gKDsaKU3/lib/python3.8/site-packages/django/core/checks/registry.py", line 77, in run_checks
    new_errors = check(app_configs=app_configs, databases=databases)
  File "/home/vagrant/.local/share/virtualenvs/vagrant-gKDsaKU3/lib/python3.8/site-packages/django/core/checks/urls.py", line 13, in check_url_config
    return check_resolver(resolver)
  File "/home/vagrant/.local/share/virtualenvs/vagrant-gKDsaKU3/lib/python3.8/site-packages/django/core/checks/urls.py", line 23, in check_resolver
    return check_method()
  File "/home/vagrant/.local/share/virtualenvs/vagrant-gKDsaKU3/lib/python3.8/site-packages/django/urls/resolvers.py", line 446, in check
    for pattern in self.url_patterns:
  File "/home/vagrant/.local/share/virtualenvs/vagrant-gKDsaKU3/lib/python3.8/site-packages/django/utils/functional.py", line 48, in __get__
    res = instance.__dict__[self.name] = self.func(instance)
  File "/home/vagrant/.local/share/virtualenvs/vagrant-gKDsaKU3/lib/python3.8/site-packages/django/urls/resolvers.py", line 632, in url_patterns
    patterns = getattr(self.urlconf_module, "urlpatterns", self.urlconf_module)
  File "/home/vagrant/.local/share/virtualenvs/vagrant-gKDsaKU3/lib/python3.8/site-packages/django/utils/functional.py", line 48, in __get__
    res = instance.__dict__[self.name] = self.func(instance)
  File "/home/vagrant/.local/share/virtualenvs/vagrant-gKDsaKU3/lib/python3.8/site-packages/django/urls/resolvers.py", line 625, in urlconf_module
    return import_module(self.urlconf_name)
  File "/home/vagrant/.local/share/virtualenvs/vagrant-gKDsaKU3/lib64/python3.8/importlib/__init__.py", line 127, in import_module
    return _bootstrap._gcd_import(name[level:], package, level)
  File "<frozen importlib._bootstrap>", line 1014, in _gcd_import
  File "<frozen importlib._bootstrap>", line 991, in _find_and_load
  File "<frozen importlib._bootstrap>", line 975, in _find_and_load_unlocked
  File "<frozen importlib._bootstrap>", line 671, in _load_unlocked
  File "<frozen importlib._bootstrap_external>", line 783, in exec_module
  File "<frozen importlib._bootstrap>", line 219, in _call_with_frames_removed
  File "/vagrant/beyond_tutorial/urls.py", line 21, in <module>
    path('', views.board, name='board'),
NameError: name 'views' is not defined
Performing system checks...

Watching for file changes with StatReloader
Exception in thread django-main-thread:
Traceback (most recent call last):
  File "/usr/lib64/python3.8/threading.py", line 932, in _bootstrap_inner
    self.run()
  File "/usr/lib64/python3.8/threading.py", line 870, in run
    self._target(*self._args, **self._kwargs)
  File "/home/vagrant/.local/share/virtualenvs/vagrant-gKDsaKU3/lib/python3.8/site-packages/django/utils/autoreload.py", line 64, in wrapper
    fn(*args, **kwargs)
  File "/home/vagrant/.local/share/virtualenvs/vagrant-gKDsaKU3/lib/python3.8/site-packages/django/core/management/commands/runserver.py", line 124, in inner_run
    self.check(display_num_errors=True)
  File "/home/vagrant/.local/share/virtualenvs/vagrant-gKDsaKU3/lib/python3.8/site-packages/django/core/management/base.py", line 438, in check
    all_issues = checks.run_checks(
  File "/home/vagrant/.local/share/virtualenvs/vagrant-gKDsaKU3/lib/python3.8/site-packages/django/core/checks/registry.py", line 77, in run_checks
    new_errors = check(app_configs=app_configs, databases=databases)
  File "/home/vagrant/.local/share/virtualenvs/vagrant-gKDsaKU3/lib/python3.8/site-packages/django/core/checks/urls.py", line 13, in check_url_config
    return check_resolver(resolver)
  File "/home/vagrant/.local/share/virtualenvs/vagrant-gKDsaKU3/lib/python3.8/site-packages/django/core/checks/urls.py", line 23, in check_resolver
    return check_method()
  File "/home/vagrant/.local/share/virtualenvs/vagrant-gKDsaKU3/lib/python3.8/site-packages/django/urls/resolvers.py", line 446, in check
    for pattern in self.url_patterns:
  File "/home/vagrant/.local/share/virtualenvs/vagrant-gKDsaKU3/lib/python3.8/site-packages/django/utils/functional.py", line 48, in __get__
    res = instance.__dict__[self.name] = self.func(instance)
  File "/home/vagrant/.local/share/virtualenvs/vagrant-gKDsaKU3/lib/python3.8/site-packages/django/urls/resolvers.py", line 632, in url_patterns
    patterns = getattr(self.urlconf_module, "urlpatterns", self.urlconf_module)
  File "/home/vagrant/.local/share/virtualenvs/vagrant-gKDsaKU3/lib/python3.8/site-packages/django/utils/functional.py", line 48, in __get__
    res = instance.__dict__[self.name] = self.func(instance)
  File "/home/vagrant/.local/share/virtualenvs/vagrant-gKDsaKU3/lib/python3.8/site-packages/django/urls/resolvers.py", line 625, in urlconf_module
    return import_module(self.urlconf_name)
  File "/home/vagrant/.local/share/virtualenvs/vagrant-gKDsaKU3/lib64/python3.8/importlib/__init__.py", line 127, in import_module
    return _bootstrap._gcd_import(name[level:], package, level)
  File "<frozen importlib._bootstrap>", line 1014, in _gcd_import
  File "<frozen importlib._bootstrap>", line 991, in _find_and_load
  File "<frozen importlib._bootstrap>", line 975, in _find_and_load_unlocked
  File "<frozen importlib._bootstrap>", line 671, in _load_unlocked
  File "<frozen importlib._bootstrap_external>", line 783, in exec_module
  File "<frozen importlib._bootstrap>", line 219, in _call_with_frames_removed
  File "/vagrant/beyond_tutorial/urls.py", line 21, in <module>
    path('', views.board, name='board'),
NameError: name 'views' is not defined
Performing system checks...

Watching for file changes with StatReloader
Exception in thread django-main-thread:
Traceback (most recent call last):
  File "/usr/lib64/python3.8/threading.py", line 932, in _bootstrap_inner
    self.run()
  File "/usr/lib64/python3.8/threading.py", line 870, in run
    self._target(*self._args, **self._kwargs)
  File "/home/vagrant/.local/share/virtualenvs/vagrant-gKDsaKU3/lib/python3.8/site-packages/django/utils/autoreload.py", line 64, in wrapper
    fn(*args, **kwargs)
  File "/home/vagrant/.local/share/virtualenvs/vagrant-gKDsaKU3/lib/python3.8/site-packages/django/core/management/commands/runserver.py", line 124, in inner_run
    self.check(display_num_errors=True)
  File "/home/vagrant/.local/share/virtualenvs/vagrant-gKDsaKU3/lib/python3.8/site-packages/django/core/management/base.py", line 438, in check
    all_issues = checks.run_checks(
  File "/home/vagrant/.local/share/virtualenvs/vagrant-gKDsaKU3/lib/python3.8/site-packages/django/core/checks/registry.py", line 77, in run_checks
    new_errors = check(app_configs=app_configs, databases=databases)
  File "/home/vagrant/.local/share/virtualenvs/vagrant-gKDsaKU3/lib/python3.8/site-packages/django/core/checks/urls.py", line 13, in check_url_config
    return check_resolver(resolver)
  File "/home/vagrant/.local/share/virtualenvs/vagrant-gKDsaKU3/lib/python3.8/site-packages/django/core/checks/urls.py", line 23, in check_resolver
    return check_method()
  File "/home/vagrant/.local/share/virtualenvs/vagrant-gKDsaKU3/lib/python3.8/site-packages/django/urls/resolvers.py", line 446, in check
    for pattern in self.url_patterns:
  File "/home/vagrant/.local/share/virtualenvs/vagrant-gKDsaKU3/lib/python3.8/site-packages/django/utils/functional.py", line 48, in __get__
    res = instance.__dict__[self.name] = self.func(instance)
  File "/home/vagrant/.local/share/virtualenvs/vagrant-gKDsaKU3/lib/python3.8/site-packages/django/urls/resolvers.py", line 632, in url_patterns
    patterns = getattr(self.urlconf_module, "urlpatterns", self.urlconf_module)
  File "/home/vagrant/.local/share/virtualenvs/vagrant-gKDsaKU3/lib/python3.8/site-packages/django/utils/functional.py", line 48, in __get__
    res = instance.__dict__[self.name] = self.func(instance)
  File "/home/vagrant/.local/share/virtualenvs/vagrant-gKDsaKU3/lib/python3.8/site-packages/django/urls/resolvers.py", line 625, in urlconf_module
    return import_module(self.urlconf_name)
  File "/home/vagrant/.local/share/virtualenvs/vagrant-gKDsaKU3/lib64/python3.8/importlib/__init__.py", line 127, in import_module
    return _bootstrap._gcd_import(name[level:], package, level)
  File "<frozen importlib._bootstrap>", line 1014, in _gcd_import
  File "<frozen importlib._bootstrap>", line 991, in _find_and_load
  File "<frozen importlib._bootstrap>", line 975, in _find_and_load_unlocked
  File "<frozen importlib._bootstrap>", line 671, in _load_unlocked
  File "<frozen importlib._bootstrap_external>", line 783, in exec_module
  File "<frozen importlib._bootstrap>", line 219, in _call_with_frames_removed
  File "/vagrant/beyond_tutorial/urls.py", line 21, in <module>
    path('', views.board, name='board'),
NameError: name 'views' is not defined
Watching for file changes with StatReloader
Exception in thread django-main-thread:
Traceback (most recent call last):
  File "/usr/lib64/python3.8/threading.py", line 932, in _bootstrap_inner
    self.run()
  File "/usr/lib64/python3.8/threading.py", line 870, in run
    self._target(*self._args, **self._kwargs)
  File "/home/vagrant/.local/share/virtualenvs/vagrant-gKDsaKU3/lib/python3.8/site-packages/django/utils/autoreload.py", line 64, in wrapper
    fn(*args, **kwargs)
  File "/home/vagrant/.local/share/virtualenvs/vagrant-gKDsaKU3/lib/python3.8/site-packages/django/core/management/commands/runserver.py", line 124, in inner_run
    self.check(display_num_errors=True)
  File "/home/vagrant/.local/share/virtualenvs/vagrant-gKDsaKU3/lib/python3.8/site-packages/django/core/management/base.py", line 438, in check
    all_issues = checks.run_checks(
  File "/home/vagrant/.local/share/virtualenvs/vagrant-gKDsaKU3/lib/python3.8/site-packages/django/core/checks/registry.py", line 77, in run_checks
    new_errors = check(app_configs=app_configs, databases=databases)
  File "/home/vagrant/.local/share/virtualenvs/vagrant-gKDsaKU3/lib/python3.8/site-packages/django/core/checks/urls.py", line 13, in check_url_config
    return check_resolver(resolver)
  File "/home/vagrant/.local/share/virtualenvs/vagrant-gKDsaKU3/lib/python3.8/site-packages/django/core/checks/urls.py", line 23, in check_resolver
    return check_method()
  File "/home/vagrant/.local/share/virtualenvs/vagrant-gKDsaKU3/lib/python3.8/site-packages/django/urls/resolvers.py", line 446, in check
    for pattern in self.url_patterns:
  File "/home/vagrant/.local/share/virtualenvs/vagrant-gKDsaKU3/lib/python3.8/site-packages/django/utils/functional.py", line 48, in __get__
    res = instance.__dict__[self.name] = self.func(instance)
  File "/home/vagrant/.local/share/virtualenvs/vagrant-gKDsaKU3/lib/python3.8/site-packages/django/urls/resolvers.py", line 632, in url_patterns
    patterns = getattr(self.urlconf_module, "urlpatterns", self.urlconf_module)
  File "/home/vagrant/.local/share/virtualenvs/vagrant-gKDsaKU3/lib/python3.8/site-packages/django/utils/functional.py", line 48, in __get__
    res = instance.__dict__[self.name] = self.func(instance)
  File "/home/vagrant/.local/share/virtualenvs/vagrant-gKDsaKU3/lib/python3.8/site-packages/django/urls/resolvers.py", line 625, in urlconf_module
    return import_module(self.urlconf_name)
  File "/home/vagrant/.local/share/virtualenvs/vagrant-gKDsaKU3/lib64/python3.8/importlib/__init__.py", line 127, in import_module
    return _bootstrap._gcd_import(name[level:], package, level)
  File "<frozen importlib._bootstrap>", line 1014, in _gcd_import
  File "<frozen importlib._bootstrap>", line 991, in _find_and_load
  File "<frozen importlib._bootstrap>", line 975, in _find_and_load_unlocked
  File "<frozen importlib._bootstrap>", line 671, in _load_unlocked
  File "<frozen importlib._bootstrap_external>", line 783, in exec_module
  File "<frozen importlib._bootstrap>", line 219, in _call_with_frames_removed
  File "/vagrant/beyond_tutorial/urls.py", line 21, in <module>
    path('', views.board, name='board'),
NameError: name 'views' is not defined
/vagrant/beyond_tutorial/urls.py changed, reloading.
Performing system checks...

Watching for file changes with StatReloader
Exception in thread django-main-thread:
Traceback (most recent call last):
  File "/usr/lib64/python3.8/threading.py", line 932, in _bootstrap_inner
    self.run()
  File "/usr/lib64/python3.8/threading.py", line 870, in run
    self._target(*self._args, **self._kwargs)
  File "/home/vagrant/.local/share/virtualenvs/vagrant-gKDsaKU3/lib/python3.8/site-packages/django/utils/autoreload.py", line 64, in wrapper
    fn(*args, **kwargs)
  File "/home/vagrant/.local/share/virtualenvs/vagrant-gKDsaKU3/lib/python3.8/site-packages/django/core/management/commands/runserver.py", line 124, in inner_run
    self.check(display_num_errors=True)
  File "/home/vagrant/.local/share/virtualenvs/vagrant-gKDsaKU3/lib/python3.8/site-packages/django/core/management/base.py", line 438, in check
    all_issues = checks.run_checks(
  File "/home/vagrant/.local/share/virtualenvs/vagrant-gKDsaKU3/lib/python3.8/site-packages/django/core/checks/registry.py", line 77, in run_checks
    new_errors = check(app_configs=app_configs, databases=databases)
  File "/home/vagrant/.local/share/virtualenvs/vagrant-gKDsaKU3/lib/python3.8/site-packages/django/core/checks/urls.py", line 13, in check_url_config
    return check_resolver(resolver)
  File "/home/vagrant/.local/share/virtualenvs/vagrant-gKDsaKU3/lib/python3.8/site-packages/django/core/checks/urls.py", line 23, in check_resolver
    return check_method()
  File "/home/vagrant/.local/share/virtualenvs/vagrant-gKDsaKU3/lib/python3.8/site-packages/django/urls/resolvers.py", line 446, in check
    for pattern in self.url_patterns:
  File "/home/vagrant/.local/share/virtualenvs/vagrant-gKDsaKU3/lib/python3.8/site-packages/django/utils/functional.py", line 48, in __get__
    res = instance.__dict__[self.name] = self.func(instance)
  File "/home/vagrant/.local/share/virtualenvs/vagrant-gKDsaKU3/lib/python3.8/site-packages/django/urls/resolvers.py", line 632, in url_patterns
    patterns = getattr(self.urlconf_module, "urlpatterns", self.urlconf_module)
  File "/home/vagrant/.local/share/virtualenvs/vagrant-gKDsaKU3/lib/python3.8/site-packages/django/utils/functional.py", line 48, in __get__
    res = instance.__dict__[self.name] = self.func(instance)
  File "/home/vagrant/.local/share/virtualenvs/vagrant-gKDsaKU3/lib/python3.8/site-packages/django/urls/resolvers.py", line 625, in urlconf_module
    return import_module(self.urlconf_name)
  File "/home/vagrant/.local/share/virtualenvs/vagrant-gKDsaKU3/lib64/python3.8/importlib/__init__.py", line 127, in import_module
    return _bootstrap._gcd_import(name[level:], package, level)
  File "<frozen importlib._bootstrap>", line 1014, in _gcd_import
  File "<frozen importlib._bootstrap>", line 991, in _find_and_load
  File "<frozen importlib._bootstrap>", line 975, in _find_and_load_unlocked
  File "<frozen importlib._bootstrap>", line 671, in _load_unlocked
  File "<frozen importlib._bootstrap_external>", line 783, in exec_module
  File "<frozen importlib._bootstrap>", line 219, in _call_with_frames_removed
  File "/vagrant/beyond_tutorial/urls.py", line 18, in <module>
    from msgboard import views
  File "/vagrant/msgboard/views.py", line 4
    messages = Message.objects.order_by('-date')
    ^
IndentationError: expected an indented block
/vagrant/beyond_tutorial/urls.py changed, reloading.
Performing system checks...

Watching for file changes with StatReloader
Exception in thread django-main-thread:
Traceback (most recent call last):
  File "/usr/lib64/python3.8/threading.py", line 932, in _bootstrap_inner
    self.run()
  File "/usr/lib64/python3.8/threading.py", line 870, in run
    self._target(*self._args, **self._kwargs)
  File "/home/vagrant/.local/share/virtualenvs/vagrant-gKDsaKU3/lib/python3.8/site-packages/django/utils/autoreload.py", line 64, in wrapper
    fn(*args, **kwargs)
  File "/home/vagrant/.local/share/virtualenvs/vagrant-gKDsaKU3/lib/python3.8/site-packages/django/core/management/commands/runserver.py", line 124, in inner_run
    self.check(display_num_errors=True)
  File "/home/vagrant/.local/share/virtualenvs/vagrant-gKDsaKU3/lib/python3.8/site-packages/django/core/management/base.py", line 438, in check
    all_issues = checks.run_checks(
  File "/home/vagrant/.local/share/virtualenvs/vagrant-gKDsaKU3/lib/python3.8/site-packages/django/core/checks/registry.py", line 77, in run_checks
    new_errors = check(app_configs=app_configs, databases=databases)
  File "/home/vagrant/.local/share/virtualenvs/vagrant-gKDsaKU3/lib/python3.8/site-packages/django/core/checks/urls.py", line 13, in check_url_config
    return check_resolver(resolver)
  File "/home/vagrant/.local/share/virtualenvs/vagrant-gKDsaKU3/lib/python3.8/site-packages/django/core/checks/urls.py", line 23, in check_resolver
    return check_method()
  File "/home/vagrant/.local/share/virtualenvs/vagrant-gKDsaKU3/lib/python3.8/site-packages/django/urls/resolvers.py", line 446, in check
    for pattern in self.url_patterns:
  File "/home/vagrant/.local/share/virtualenvs/vagrant-gKDsaKU3/lib/python3.8/site-packages/django/utils/functional.py", line 48, in __get__
    res = instance.__dict__[self.name] = self.func(instance)
  File "/home/vagrant/.local/share/virtualenvs/vagrant-gKDsaKU3/lib/python3.8/site-packages/django/urls/resolvers.py", line 632, in url_patterns
    patterns = getattr(self.urlconf_module, "urlpatterns", self.urlconf_module)
  File "/home/vagrant/.local/share/virtualenvs/vagrant-gKDsaKU3/lib/python3.8/site-packages/django/utils/functional.py", line 48, in __get__
    res = instance.__dict__[self.name] = self.func(instance)
  File "/home/vagrant/.local/share/virtualenvs/vagrant-gKDsaKU3/lib/python3.8/site-packages/django/urls/resolvers.py", line 625, in urlconf_module
    return import_module(self.urlconf_name)
  File "/home/vagrant/.local/share/virtualenvs/vagrant-gKDsaKU3/lib64/python3.8/importlib/__init__.py", line 127, in import_module
    return _bootstrap._gcd_import(name[level:], package, level)
  File "<frozen importlib._bootstrap>", line 1014, in _gcd_import
  File "<frozen importlib._bootstrap>", line 991, in _find_and_load
  File "<frozen importlib._bootstrap>", line 975, in _find_and_load_unlocked
  File "<frozen importlib._bootstrap>", line 671, in _load_unlocked
  File "<frozen importlib._bootstrap_external>", line 783, in exec_module
  File "<frozen importlib._bootstrap>", line 219, in _call_with_frames_removed
  File "/vagrant/beyond_tutorial/urls.py", line 18, in <module>
    from msgboard import views
  File "/vagrant/msgboard/views.py", line 4
    messages = Message.objects.order_by('-date')
    ^
IndentationError: expected an indented block
/vagrant/msgboard/views.py changed, reloading.
Performing system checks...

Watching for file changes with StatReloader
/vagrant/msgboard/views.py changed, reloading.
Performing system checks...

Watching for file changes with StatReloader
[01/Feb/2022 02:16:29] "GET / HTTP/1.1" 200 557
/vagrant/msgboard/views.py changed, reloading.
Performing system checks...

System check identified no issues (0 silenced).
February 01, 2022 - 02:16:03
Django version 4.0.1, using settings 'beyond_tutorial.settings'
Starting development server at http://0.0.0.0:8000/
Quit the server with CONTROL-C.
Watching for file changes with StatReloader
[01/Feb/2022 02:22:07] "GET / HTTP/1.1" 200 1107
[01/Feb/2022 02:22:21] "POST / HTTP/1.1" 302 0
[01/Feb/2022 02:22:21] "GET / HTTP/1.1" 200 1289
[01/Feb/2022 02:22:40] "POST / HTTP/1.1" 302 0
[01/Feb/2022 02:22:40] "GET / HTTP/1.1" 200 1436
